2023-11-03T16:56:27.470051-0600 WARNING Short URL does not exist
2023-11-03T16:56:27.470051-0600 WARNING Short URL does not exist
2023-11-03T16:56:27.475060-0600 INFO Retrieved original URL for short URL: validShort
2023-11-03T16:57:50.658116-0600 WARNING Short URL does not exist
2023-11-03T16:57:50.658116-0600 WARNING Short URL does not exist
2023-11-03T16:57:50.658116-0600 INFO Retrieved original URL for short URL: validShort
2023-11-03T16:58:05.181198-0600 ERROR Error retrieving all URLs: DB connection error
Traceback (most recent call last):

  File "C:\Users\Camden\AppData\Local\Programs\Python\Python39\lib\runpy.py", line 197, in _run_module_as_main
    return _run_code(code, main_globals, None,
           │         │     └ {'__name__': '__main__', '__doc__': 'Main entry point', '__package__': 'unittest', '__loader__': <_frozen_importlib_external....
           │         └ <code object <module> at 0x000001CFEFD7B030, file "C:\Users\Camden\AppData\Local\Programs\Python\Python39\lib\unittest\__main...
           └ <function _run_code at 0x000001CFEF9BF310>

  File "C:\Users\Camden\AppData\Local\Programs\Python\Python39\lib\runpy.py", line 87, in _run_code
    exec(code, run_globals)
         │     └ {'__name__': '__main__', '__doc__': 'Main entry point', '__package__': 'unittest', '__loader__': <_frozen_importlib_external....
         └ <code object <module> at 0x000001CFEFD7B030, file "C:\Users\Camden\AppData\Local\Programs\Python\Python39\lib\unittest\__main...

  File "C:\Users\Camden\AppData\Local\Programs\Python\Python39\lib\unittest\__main__.py", line 18, in <module>
    main(module=None)
    └ <class 'unittest.main.TestProgram'>

  File "C:\Users\Camden\AppData\Local\Programs\Python\Python39\lib\unittest\main.py", line 101, in __init__
    self.runTests()
    │    └ <function TestProgram.runTests at 0x000001CFEFDC3430>
    └ <unittest.main.TestProgram object at 0x000001CFEF9AED00>

  File "C:\Users\Camden\AppData\Local\Programs\Python\Python39\lib\unittest\main.py", line 271, in runTests
    self.result = testRunner.run(self.test)
    │             │          │   │    └ <unittest.suite.TestSuite tests=[<unittest.suite.TestSuite tests=[<unittest.suite.TestSuite tests=[<tests.test_url_listing.Te...
    │             │          │   └ <unittest.main.TestProgram object at 0x000001CFEF9AED00>
    │             │          └ <function TextTestRunner.run at 0x000001CFEFDC0D30>
    │             └ <unittest.runner.TextTestRunner object at 0x000001CFEF9C1AC0>
    └ <unittest.main.TestProgram object at 0x000001CFEF9AED00>

  File "C:\Users\Camden\AppData\Local\Programs\Python\Python39\lib\unittest\runner.py", line 176, in run
    test(result)
    │    └ <unittest.runner.TextTestResult run=1 errors=0 failures=0>
    └ <unittest.suite.TestSuite tests=[<unittest.suite.TestSuite tests=[<unittest.suite.TestSuite tests=[<tests.test_url_listing.Te...

  File "C:\Users\Camden\AppData\Local\Programs\Python\Python39\lib\unittest\suite.py", line 84, in __call__
    return self.run(*args, **kwds)
           │    │    │       └ {}
           │    │    └ (<unittest.runner.TextTestResult run=1 errors=0 failures=0>,)
           │    └ <function TestSuite.run at 0x000001CFEFD62940>
           └ <unittest.suite.TestSuite tests=[<unittest.suite.TestSuite tests=[<unittest.suite.TestSuite tests=[<tests.test_url_listing.Te...

  File "C:\Users\Camden\AppData\Local\Programs\Python\Python39\lib\unittest\suite.py", line 122, in run
    test(result)
    │    └ <unittest.runner.TextTestResult run=1 errors=0 failures=0>
    └ <unittest.suite.TestSuite tests=[<unittest.suite.TestSuite tests=[<tests.test_url_listing.TestURLListing testMethod=test_list...

  File "C:\Users\Camden\AppData\Local\Programs\Python\Python39\lib\unittest\suite.py", line 84, in __call__
    return self.run(*args, **kwds)
           │    │    │       └ {}
           │    │    └ (<unittest.runner.TextTestResult run=1 errors=0 failures=0>,)
           │    └ <function TestSuite.run at 0x000001CFEFD62940>
           └ <unittest.suite.TestSuite tests=[<unittest.suite.TestSuite tests=[<tests.test_url_listing.TestURLListing testMethod=test_list...

  File "C:\Users\Camden\AppData\Local\Programs\Python\Python39\lib\unittest\suite.py", line 122, in run
    test(result)
    │    └ <unittest.runner.TextTestResult run=1 errors=0 failures=0>
    └ <unittest.suite.TestSuite tests=[<tests.test_url_listing.TestURLListing testMethod=test_listing_with_db_error>, <tests.test_u...

  File "C:\Users\Camden\AppData\Local\Programs\Python\Python39\lib\unittest\suite.py", line 84, in __call__
    return self.run(*args, **kwds)
           │    │    │       └ {}
           │    │    └ (<unittest.runner.TextTestResult run=1 errors=0 failures=0>,)
           │    └ <function TestSuite.run at 0x000001CFEFD62940>
           └ <unittest.suite.TestSuite tests=[<tests.test_url_listing.TestURLListing testMethod=test_listing_with_db_error>, <tests.test_u...

  File "C:\Users\Camden\AppData\Local\Programs\Python\Python39\lib\unittest\suite.py", line 122, in run
    test(result)
    │    └ <unittest.runner.TextTestResult run=1 errors=0 failures=0>
    └ <tests.test_url_listing.TestURLListing testMethod=test_listing_with_db_error>

  File "C:\Users\Camden\AppData\Local\Programs\Python\Python39\lib\unittest\case.py", line 653, in __call__
    return self.run(*args, **kwds)
           │    │    │       └ {}
           │    │    └ (<unittest.runner.TextTestResult run=1 errors=0 failures=0>,)
           │    └ <function TestCase.run at 0x000001CFEFD5C790>
           └ <tests.test_url_listing.TestURLListing testMethod=test_listing_with_db_error>

  File "C:\Users\Camden\AppData\Local\Programs\Python\Python39\lib\unittest\case.py", line 593, in run
    self._callTestMethod(testMethod)
    │    │               └ <bound method TestURLListing.test_listing_with_db_error of <tests.test_url_listing.TestURLListing testMethod=test_listing_wit...
    │    └ <function TestCase._callTestMethod at 0x000001CFEFD5C5E0>
    └ <tests.test_url_listing.TestURLListing testMethod=test_listing_with_db_error>

  File "C:\Users\Camden\AppData\Local\Programs\Python\Python39\lib\unittest\case.py", line 550, in _callTestMethod
    method()
    └ <bound method TestURLListing.test_listing_with_db_error of <tests.test_url_listing.TestURLListing testMethod=test_listing_wit...

  File "C:\Users\Camden\AppData\Local\Programs\Python\Python39\lib\unittest\mock.py", line 1337, in patched
    return func(*newargs, **newkeywargs)
           │     │          └ {}
           │     └ (<tests.test_url_listing.TestURLListing testMethod=test_listing_with_db_error>, <MagicMock name='scan' id='1992678356640'>)
           └ <function TestURLListing.test_listing_with_db_error at 0x000001CFF50A8670>

  File "C:\Users\Camden\PycharmProjects\url-shortener\tests\test_url_listing.py", line 28, in test_listing_with_db_error
    get_all_urls()
    └ <function get_all_urls at 0x000001CFF4B32040>

> File "C:\Users\Camden\PycharmProjects\url-shortener\service\db_service.py", line 50, in get_all_urls
    urls = [item for item in URLModel.scan()]
                             │        └ <MagicMock name='scan' id='1992678356640'>
                             └ <class 'models.db_models.URLModel'>

  File "C:\Users\Camden\AppData\Local\Programs\Python\Python39\lib\unittest\mock.py", line 1093, in __call__
    return self._mock_call(*args, **kwargs)
           │    │           │       └ {}
           │    │           └ ()
           │    └ <function CallableMixin._mock_call at 0x000001CFF1AEC700>
           └ <MagicMock name='scan' id='1992678356640'>

  File "C:\Users\Camden\AppData\Local\Programs\Python\Python39\lib\unittest\mock.py", line 1097, in _mock_call
    return self._execute_mock_call(*args, **kwargs)
           │    │                   │       └ {}
           │    │                   └ ()
           │    └ <function CallableMixin._execute_mock_call at 0x000001CFF1AEC820>
           └ <MagicMock name='scan' id='1992678356640'>

  File "C:\Users\Camden\AppData\Local\Programs\Python\Python39\lib\unittest\mock.py", line 1152, in _execute_mock_call
    raise effect
          └ ConnectionError('DB connection error')

ConnectionError: DB connection error
2023-11-03T16:58:05.248576-0600 INFO Retrieved all URLs from the database.
2023-11-03T16:58:05.248576-0600 INFO Retrieved all URLs from the database.
2023-11-03T17:01:12.104113-0600 ERROR Error retrieving all URLs: DB connection error
Traceback (most recent call last):

  File "C:\Users\Camden\AppData\Local\Programs\Python\Python39\lib\runpy.py", line 197, in _run_module_as_main
    return _run_code(code, main_globals, None,
           │         │     └ {'__name__': '__main__', '__doc__': 'Main entry point', '__package__': 'unittest', '__loader__': <_frozen_importlib_external....
           │         └ <code object <module> at 0x000001BC0A41C030, file "C:\Users\Camden\AppData\Local\Programs\Python\Python39\lib\unittest\__main...
           └ <function _run_code at 0x000001BC0A05F310>

  File "C:\Users\Camden\AppData\Local\Programs\Python\Python39\lib\runpy.py", line 87, in _run_code
    exec(code, run_globals)
         │     └ {'__name__': '__main__', '__doc__': 'Main entry point', '__package__': 'unittest', '__loader__': <_frozen_importlib_external....
         └ <code object <module> at 0x000001BC0A41C030, file "C:\Users\Camden\AppData\Local\Programs\Python\Python39\lib\unittest\__main...

  File "C:\Users\Camden\AppData\Local\Programs\Python\Python39\lib\unittest\__main__.py", line 18, in <module>
    main(module=None)
    └ <class 'unittest.main.TestProgram'>

  File "C:\Users\Camden\AppData\Local\Programs\Python\Python39\lib\unittest\main.py", line 101, in __init__
    self.runTests()
    │    └ <function TestProgram.runTests at 0x000001BC0A463430>
    └ <unittest.main.TestProgram object at 0x000001BC0A04ED00>

  File "C:\Users\Camden\AppData\Local\Programs\Python\Python39\lib\unittest\main.py", line 271, in runTests
    self.result = testRunner.run(self.test)
    │             │          │   │    └ <unittest.suite.TestSuite tests=[<unittest.suite.TestSuite tests=[<unittest.suite.TestSuite tests=[<tests.test_url_listing.Te...
    │             │          │   └ <unittest.main.TestProgram object at 0x000001BC0A04ED00>
    │             │          └ <function TextTestRunner.run at 0x000001BC0A460D30>
    │             └ <unittest.runner.TextTestRunner object at 0x000001BC0A061AC0>
    └ <unittest.main.TestProgram object at 0x000001BC0A04ED00>

  File "C:\Users\Camden\AppData\Local\Programs\Python\Python39\lib\unittest\runner.py", line 176, in run
    test(result)
    │    └ <unittest.runner.TextTestResult run=1 errors=0 failures=0>
    └ <unittest.suite.TestSuite tests=[<unittest.suite.TestSuite tests=[<unittest.suite.TestSuite tests=[<tests.test_url_listing.Te...

  File "C:\Users\Camden\AppData\Local\Programs\Python\Python39\lib\unittest\suite.py", line 84, in __call__
    return self.run(*args, **kwds)
           │    │    │       └ {}
           │    │    └ (<unittest.runner.TextTestResult run=1 errors=0 failures=0>,)
           │    └ <function TestSuite.run at 0x000001BC0A402940>
           └ <unittest.suite.TestSuite tests=[<unittest.suite.TestSuite tests=[<unittest.suite.TestSuite tests=[<tests.test_url_listing.Te...

  File "C:\Users\Camden\AppData\Local\Programs\Python\Python39\lib\unittest\suite.py", line 122, in run
    test(result)
    │    └ <unittest.runner.TextTestResult run=1 errors=0 failures=0>
    └ <unittest.suite.TestSuite tests=[<unittest.suite.TestSuite tests=[<tests.test_url_listing.TestURLListing testMethod=test_list...

  File "C:\Users\Camden\AppData\Local\Programs\Python\Python39\lib\unittest\suite.py", line 84, in __call__
    return self.run(*args, **kwds)
           │    │    │       └ {}
           │    │    └ (<unittest.runner.TextTestResult run=1 errors=0 failures=0>,)
           │    └ <function TestSuite.run at 0x000001BC0A402940>
           └ <unittest.suite.TestSuite tests=[<unittest.suite.TestSuite tests=[<tests.test_url_listing.TestURLListing testMethod=test_list...

  File "C:\Users\Camden\AppData\Local\Programs\Python\Python39\lib\unittest\suite.py", line 122, in run
    test(result)
    │    └ <unittest.runner.TextTestResult run=1 errors=0 failures=0>
    └ <unittest.suite.TestSuite tests=[<tests.test_url_listing.TestURLListing testMethod=test_listing_with_db_error>, <tests.test_u...

  File "C:\Users\Camden\AppData\Local\Programs\Python\Python39\lib\unittest\suite.py", line 84, in __call__
    return self.run(*args, **kwds)
           │    │    │       └ {}
           │    │    └ (<unittest.runner.TextTestResult run=1 errors=0 failures=0>,)
           │    └ <function TestSuite.run at 0x000001BC0A402940>
           └ <unittest.suite.TestSuite tests=[<tests.test_url_listing.TestURLListing testMethod=test_listing_with_db_error>, <tests.test_u...

  File "C:\Users\Camden\AppData\Local\Programs\Python\Python39\lib\unittest\suite.py", line 122, in run
    test(result)
    │    └ <unittest.runner.TextTestResult run=1 errors=0 failures=0>
    └ <tests.test_url_listing.TestURLListing testMethod=test_listing_with_db_error>

  File "C:\Users\Camden\AppData\Local\Programs\Python\Python39\lib\unittest\case.py", line 653, in __call__
    return self.run(*args, **kwds)
           │    │    │       └ {}
           │    │    └ (<unittest.runner.TextTestResult run=1 errors=0 failures=0>,)
           │    └ <function TestCase.run at 0x000001BC0A3FC790>
           └ <tests.test_url_listing.TestURLListing testMethod=test_listing_with_db_error>

  File "C:\Users\Camden\AppData\Local\Programs\Python\Python39\lib\unittest\case.py", line 593, in run
    self._callTestMethod(testMethod)
    │    │               └ <bound method TestURLListing.test_listing_with_db_error of <tests.test_url_listing.TestURLListing testMethod=test_listing_wit...
    │    └ <function TestCase._callTestMethod at 0x000001BC0A3FC5E0>
    └ <tests.test_url_listing.TestURLListing testMethod=test_listing_with_db_error>

  File "C:\Users\Camden\AppData\Local\Programs\Python\Python39\lib\unittest\case.py", line 550, in _callTestMethod
    method()
    └ <bound method TestURLListing.test_listing_with_db_error of <tests.test_url_listing.TestURLListing testMethod=test_listing_wit...

  File "C:\Users\Camden\AppData\Local\Programs\Python\Python39\lib\unittest\mock.py", line 1337, in patched
    return func(*newargs, **newkeywargs)
           │     │          └ {}
           │     └ (<tests.test_url_listing.TestURLListing testMethod=test_listing_with_db_error>, <MagicMock name='scan' id='1907221362336'>)
           └ <function TestURLListing.test_listing_with_db_error at 0x000001BC0F778670>

  File "C:\Users\Camden\PycharmProjects\url-shortener\tests\test_url_listing.py", line 28, in test_listing_with_db_error
    get_all_urls()
    └ <function get_all_urls at 0x000001BC0F201040>

> File "C:\Users\Camden\PycharmProjects\url-shortener\service\db_service.py", line 50, in get_all_urls
    urls = [item for item in URLModel.scan()]
                             │        └ <MagicMock name='scan' id='1907221362336'>
                             └ <class 'models.db_models.URLModel'>

  File "C:\Users\Camden\AppData\Local\Programs\Python\Python39\lib\unittest\mock.py", line 1093, in __call__
    return self._mock_call(*args, **kwargs)
           │    │           │       └ {}
           │    │           └ ()
           │    └ <function CallableMixin._mock_call at 0x000001BC0C1BC700>
           └ <MagicMock name='scan' id='1907221362336'>

  File "C:\Users\Camden\AppData\Local\Programs\Python\Python39\lib\unittest\mock.py", line 1097, in _mock_call
    return self._execute_mock_call(*args, **kwargs)
           │    │                   │       └ {}
           │    │                   └ ()
           │    └ <function CallableMixin._execute_mock_call at 0x000001BC0C1BC820>
           └ <MagicMock name='scan' id='1907221362336'>

  File "C:\Users\Camden\AppData\Local\Programs\Python\Python39\lib\unittest\mock.py", line 1152, in _execute_mock_call
    raise effect
          └ ConnectionError('DB connection error')

ConnectionError: DB connection error
2023-11-03T17:01:12.114197-0600 INFO Retrieved all URLs from the database.
2023-11-03T17:01:12.114197-0600 INFO Retrieved all URLs from the database.
2023-11-03T17:02:54.808109-0600 ERROR Error retrieving all URLs: DB connection error
Traceback (most recent call last):

  File "C:\Users\Camden\AppData\Local\Programs\Python\Python39\lib\runpy.py", line 197, in _run_module_as_main
    return _run_code(code, main_globals, None,
           │         │     └ {'__name__': '__main__', '__doc__': 'Main entry point', '__package__': 'unittest', '__loader__': <_frozen_importlib_external....
           │         └ <code object <module> at 0x000001E1FBB4B030, file "C:\Users\Camden\AppData\Local\Programs\Python\Python39\lib\unittest\__main...
           └ <function _run_code at 0x000001E1FB78F310>

  File "C:\Users\Camden\AppData\Local\Programs\Python\Python39\lib\runpy.py", line 87, in _run_code
    exec(code, run_globals)
         │     └ {'__name__': '__main__', '__doc__': 'Main entry point', '__package__': 'unittest', '__loader__': <_frozen_importlib_external....
         └ <code object <module> at 0x000001E1FBB4B030, file "C:\Users\Camden\AppData\Local\Programs\Python\Python39\lib\unittest\__main...

  File "C:\Users\Camden\AppData\Local\Programs\Python\Python39\lib\unittest\__main__.py", line 18, in <module>
    main(module=None)
    └ <class 'unittest.main.TestProgram'>

  File "C:\Users\Camden\AppData\Local\Programs\Python\Python39\lib\unittest\main.py", line 101, in __init__
    self.runTests()
    │    └ <function TestProgram.runTests at 0x000001E1FBB93430>
    └ <unittest.main.TestProgram object at 0x000001E1FB77ED00>

  File "C:\Users\Camden\AppData\Local\Programs\Python\Python39\lib\unittest\main.py", line 271, in runTests
    self.result = testRunner.run(self.test)
    │             │          │   │    └ <unittest.suite.TestSuite tests=[<unittest.suite.TestSuite tests=[<unittest.suite.TestSuite tests=[<tests.test_url_listing.Te...
    │             │          │   └ <unittest.main.TestProgram object at 0x000001E1FB77ED00>
    │             │          └ <function TextTestRunner.run at 0x000001E1FBB90D30>
    │             └ <unittest.runner.TextTestRunner object at 0x000001E1FB791AC0>
    └ <unittest.main.TestProgram object at 0x000001E1FB77ED00>

  File "C:\Users\Camden\AppData\Local\Programs\Python\Python39\lib\unittest\runner.py", line 176, in run
    test(result)
    │    └ <unittest.runner.TextTestResult run=1 errors=0 failures=0>
    └ <unittest.suite.TestSuite tests=[<unittest.suite.TestSuite tests=[<unittest.suite.TestSuite tests=[<tests.test_url_listing.Te...

  File "C:\Users\Camden\AppData\Local\Programs\Python\Python39\lib\unittest\suite.py", line 84, in __call__
    return self.run(*args, **kwds)
           │    │    │       └ {}
           │    │    └ (<unittest.runner.TextTestResult run=1 errors=0 failures=0>,)
           │    └ <function TestSuite.run at 0x000001E1FBB32940>
           └ <unittest.suite.TestSuite tests=[<unittest.suite.TestSuite tests=[<unittest.suite.TestSuite tests=[<tests.test_url_listing.Te...

  File "C:\Users\Camden\AppData\Local\Programs\Python\Python39\lib\unittest\suite.py", line 122, in run
    test(result)
    │    └ <unittest.runner.TextTestResult run=1 errors=0 failures=0>
    └ <unittest.suite.TestSuite tests=[<unittest.suite.TestSuite tests=[<tests.test_url_listing.TestURLListing testMethod=test_list...

  File "C:\Users\Camden\AppData\Local\Programs\Python\Python39\lib\unittest\suite.py", line 84, in __call__
    return self.run(*args, **kwds)
           │    │    │       └ {}
           │    │    └ (<unittest.runner.TextTestResult run=1 errors=0 failures=0>,)
           │    └ <function TestSuite.run at 0x000001E1FBB32940>
           └ <unittest.suite.TestSuite tests=[<unittest.suite.TestSuite tests=[<tests.test_url_listing.TestURLListing testMethod=test_list...

  File "C:\Users\Camden\AppData\Local\Programs\Python\Python39\lib\unittest\suite.py", line 122, in run
    test(result)
    │    └ <unittest.runner.TextTestResult run=1 errors=0 failures=0>
    └ <unittest.suite.TestSuite tests=[<tests.test_url_listing.TestURLListing testMethod=test_listing_with_db_error>, <tests.test_u...

  File "C:\Users\Camden\AppData\Local\Programs\Python\Python39\lib\unittest\suite.py", line 84, in __call__
    return self.run(*args, **kwds)
           │    │    │       └ {}
           │    │    └ (<unittest.runner.TextTestResult run=1 errors=0 failures=0>,)
           │    └ <function TestSuite.run at 0x000001E1FBB32940>
           └ <unittest.suite.TestSuite tests=[<tests.test_url_listing.TestURLListing testMethod=test_listing_with_db_error>, <tests.test_u...

  File "C:\Users\Camden\AppData\Local\Programs\Python\Python39\lib\unittest\suite.py", line 122, in run
    test(result)
    │    └ <unittest.runner.TextTestResult run=1 errors=0 failures=0>
    └ <tests.test_url_listing.TestURLListing testMethod=test_listing_with_db_error>

  File "C:\Users\Camden\AppData\Local\Programs\Python\Python39\lib\unittest\case.py", line 653, in __call__
    return self.run(*args, **kwds)
           │    │    │       └ {}
           │    │    └ (<unittest.runner.TextTestResult run=1 errors=0 failures=0>,)
           │    └ <function TestCase.run at 0x000001E1FBB2C790>
           └ <tests.test_url_listing.TestURLListing testMethod=test_listing_with_db_error>

  File "C:\Users\Camden\AppData\Local\Programs\Python\Python39\lib\unittest\case.py", line 593, in run
    self._callTestMethod(testMethod)
    │    │               └ <bound method TestURLListing.test_listing_with_db_error of <tests.test_url_listing.TestURLListing testMethod=test_listing_wit...
    │    └ <function TestCase._callTestMethod at 0x000001E1FBB2C5E0>
    └ <tests.test_url_listing.TestURLListing testMethod=test_listing_with_db_error>

  File "C:\Users\Camden\AppData\Local\Programs\Python\Python39\lib\unittest\case.py", line 550, in _callTestMethod
    method()
    └ <bound method TestURLListing.test_listing_with_db_error of <tests.test_url_listing.TestURLListing testMethod=test_listing_wit...

  File "C:\Users\Camden\AppData\Local\Programs\Python\Python39\lib\unittest\mock.py", line 1337, in patched
    return func(*newargs, **newkeywargs)
           │     │          └ {}
           │     └ (<tests.test_url_listing.TestURLListing testMethod=test_listing_with_db_error>, <MagicMock name='scan' id='2070170528160'>)
           └ <function TestURLListing.test_listing_with_db_error at 0x000001E1FFEE7670>

  File "C:\Users\Camden\PycharmProjects\url-shortener\tests\test_url_listing.py", line 28, in test_listing_with_db_error
    get_all_urls()
    └ <function get_all_urls at 0x000001E1FF972040>

> File "C:\Users\Camden\PycharmProjects\url-shortener\service\db_service.py", line 50, in get_all_urls
    urls = [item for item in URLModel.scan()]
                             │        └ <MagicMock name='scan' id='2070170528160'>
                             └ <class 'models.db_models.URLModel'>

  File "C:\Users\Camden\AppData\Local\Programs\Python\Python39\lib\unittest\mock.py", line 1093, in __call__
    return self._mock_call(*args, **kwargs)
           │    │           │       └ {}
           │    │           └ ()
           │    └ <function CallableMixin._mock_call at 0x000001E1FD8FC700>
           └ <MagicMock name='scan' id='2070170528160'>

  File "C:\Users\Camden\AppData\Local\Programs\Python\Python39\lib\unittest\mock.py", line 1097, in _mock_call
    return self._execute_mock_call(*args, **kwargs)
           │    │                   │       └ {}
           │    │                   └ ()
           │    └ <function CallableMixin._execute_mock_call at 0x000001E1FD8FC820>
           └ <MagicMock name='scan' id='2070170528160'>

  File "C:\Users\Camden\AppData\Local\Programs\Python\Python39\lib\unittest\mock.py", line 1152, in _execute_mock_call
    raise effect
          └ ConnectionError('DB connection error')

ConnectionError: DB connection error
2023-11-03T17:02:54.827627-0600 INFO Retrieved all URLs from the database.
2023-11-03T17:02:54.827627-0600 INFO Retrieved all URLs from the database.
2023-11-03T17:13:05.137101-0600 WARNING Short URL 'customShort' already exists.
2023-11-03T17:13:05.137101-0600 ERROR Error in shorten_url: 
2023-11-03T17:13:05.143110-0600 INFO Generated short URL: http://127.0.0.1:8000/876d8078c7
2023-11-03T17:13:05.143110-0600 INFO Generated short URL: http://127.0.0.1:8000/876d8078c7
2023-11-03T17:13:05.147195-0600 INFO Generated short URL: http://127.0.0.1:8000/fa600db0a4
2023-11-03T17:13:05.147195-0600 INFO Generated short URL: http://127.0.0.1:8000/fa600db0a4
2023-11-03T17:13:05.159007-0600 INFO Created custom short URL: customShort
2023-11-03T17:13:05.159007-0600 INFO Created custom short URL: customShort
2023-11-03T17:14:18.779413-0600 WARNING Short URL 'customShort' already exists.
2023-11-03T17:14:18.779413-0600 ERROR Error in shorten_url: 
2023-11-03T17:14:18.789464-0600 INFO Generated short URL: http://127.0.0.1:8000/cfe63c6359
2023-11-03T17:14:18.789464-0600 INFO Generated short URL: http://127.0.0.1:8000/cfe63c6359
2023-11-03T17:14:18.799207-0600 INFO Generated short URL: http://127.0.0.1:8000/6999313e1e
2023-11-03T17:14:18.799207-0600 INFO Generated short URL: http://127.0.0.1:8000/6999313e1e
2023-11-03T17:14:18.804258-0600 INFO Created custom short URL: customShort
2023-11-03T17:14:18.804258-0600 INFO Created custom short URL: customShort
2023-11-03T17:15:08.160982-0600 WARNING Short URL 'customShort' already exists.
2023-11-03T17:15:08.160982-0600 ERROR Error in shorten_url: 
2023-11-03T17:15:08.166507-0600 INFO Generated short URL: http://127.0.0.1:8000/59408d0652
2023-11-03T17:15:08.166507-0600 INFO Generated short URL: http://127.0.0.1:8000/59408d0652
2023-11-03T17:15:08.171017-0600 INFO Generated short URL: http://127.0.0.1:8000/ea886e3009
2023-11-03T17:15:08.171017-0600 INFO Generated short URL: http://127.0.0.1:8000/ea886e3009
2023-11-03T17:15:08.182174-0600 INFO Created custom short URL: customShort
2023-11-03T17:15:08.182174-0600 INFO Created custom short URL: customShort
2023-11-03T17:15:12.291340-0600 ERROR Error retrieving all URLs: DB connection error
Traceback (most recent call last):

  File "C:\Users\Camden\AppData\Local\Programs\Python\Python39\lib\runpy.py", line 197, in _run_module_as_main
    return _run_code(code, main_globals, None,
           │         │     └ {'__name__': '__main__', '__doc__': 'Main entry point', '__package__': 'unittest', '__loader__': <_frozen_importlib_external....
           │         └ <code object <module> at 0x0000022C050EB030, file "C:\Users\Camden\AppData\Local\Programs\Python\Python39\lib\unittest\__main...
           └ <function _run_code at 0x0000022C04D2F310>

  File "C:\Users\Camden\AppData\Local\Programs\Python\Python39\lib\runpy.py", line 87, in _run_code
    exec(code, run_globals)
         │     └ {'__name__': '__main__', '__doc__': 'Main entry point', '__package__': 'unittest', '__loader__': <_frozen_importlib_external....
         └ <code object <module> at 0x0000022C050EB030, file "C:\Users\Camden\AppData\Local\Programs\Python\Python39\lib\unittest\__main...

  File "C:\Users\Camden\AppData\Local\Programs\Python\Python39\lib\unittest\__main__.py", line 18, in <module>
    main(module=None)
    └ <class 'unittest.main.TestProgram'>

  File "C:\Users\Camden\AppData\Local\Programs\Python\Python39\lib\unittest\main.py", line 101, in __init__
    self.runTests()
    │    └ <function TestProgram.runTests at 0x0000022C05133430>
    └ <unittest.main.TestProgram object at 0x0000022C04D1ED00>

  File "C:\Users\Camden\AppData\Local\Programs\Python\Python39\lib\unittest\main.py", line 271, in runTests
    self.result = testRunner.run(self.test)
    │             │          │   │    └ <unittest.suite.TestSuite tests=[<unittest.suite.TestSuite tests=[<unittest.suite.TestSuite tests=[<tests.test_url_listing.Te...
    │             │          │   └ <unittest.main.TestProgram object at 0x0000022C04D1ED00>
    │             │          └ <function TextTestRunner.run at 0x0000022C05130D30>
    │             └ <unittest.runner.TextTestRunner object at 0x0000022C04D31AC0>
    └ <unittest.main.TestProgram object at 0x0000022C04D1ED00>

  File "C:\Users\Camden\AppData\Local\Programs\Python\Python39\lib\unittest\runner.py", line 176, in run
    test(result)
    │    └ <unittest.runner.TextTestResult run=1 errors=0 failures=0>
    └ <unittest.suite.TestSuite tests=[<unittest.suite.TestSuite tests=[<unittest.suite.TestSuite tests=[<tests.test_url_listing.Te...

  File "C:\Users\Camden\AppData\Local\Programs\Python\Python39\lib\unittest\suite.py", line 84, in __call__
    return self.run(*args, **kwds)
           │    │    │       └ {}
           │    │    └ (<unittest.runner.TextTestResult run=1 errors=0 failures=0>,)
           │    └ <function TestSuite.run at 0x0000022C050D2940>
           └ <unittest.suite.TestSuite tests=[<unittest.suite.TestSuite tests=[<unittest.suite.TestSuite tests=[<tests.test_url_listing.Te...

  File "C:\Users\Camden\AppData\Local\Programs\Python\Python39\lib\unittest\suite.py", line 122, in run
    test(result)
    │    └ <unittest.runner.TextTestResult run=1 errors=0 failures=0>
    └ <unittest.suite.TestSuite tests=[<unittest.suite.TestSuite tests=[<tests.test_url_listing.TestURLListing testMethod=test_list...

  File "C:\Users\Camden\AppData\Local\Programs\Python\Python39\lib\unittest\suite.py", line 84, in __call__
    return self.run(*args, **kwds)
           │    │    │       └ {}
           │    │    └ (<unittest.runner.TextTestResult run=1 errors=0 failures=0>,)
           │    └ <function TestSuite.run at 0x0000022C050D2940>
           └ <unittest.suite.TestSuite tests=[<unittest.suite.TestSuite tests=[<tests.test_url_listing.TestURLListing testMethod=test_list...

  File "C:\Users\Camden\AppData\Local\Programs\Python\Python39\lib\unittest\suite.py", line 122, in run
    test(result)
    │    └ <unittest.runner.TextTestResult run=1 errors=0 failures=0>
    └ <unittest.suite.TestSuite tests=[<tests.test_url_listing.TestURLListing testMethod=test_listing_with_db_error>, <tests.test_u...

  File "C:\Users\Camden\AppData\Local\Programs\Python\Python39\lib\unittest\suite.py", line 84, in __call__
    return self.run(*args, **kwds)
           │    │    │       └ {}
           │    │    └ (<unittest.runner.TextTestResult run=1 errors=0 failures=0>,)
           │    └ <function TestSuite.run at 0x0000022C050D2940>
           └ <unittest.suite.TestSuite tests=[<tests.test_url_listing.TestURLListing testMethod=test_listing_with_db_error>, <tests.test_u...

  File "C:\Users\Camden\AppData\Local\Programs\Python\Python39\lib\unittest\suite.py", line 122, in run
    test(result)
    │    └ <unittest.runner.TextTestResult run=1 errors=0 failures=0>
    └ <tests.test_url_listing.TestURLListing testMethod=test_listing_with_db_error>

  File "C:\Users\Camden\AppData\Local\Programs\Python\Python39\lib\unittest\case.py", line 653, in __call__
    return self.run(*args, **kwds)
           │    │    │       └ {}
           │    │    └ (<unittest.runner.TextTestResult run=1 errors=0 failures=0>,)
           │    └ <function TestCase.run at 0x0000022C050CC790>
           └ <tests.test_url_listing.TestURLListing testMethod=test_listing_with_db_error>

  File "C:\Users\Camden\AppData\Local\Programs\Python\Python39\lib\unittest\case.py", line 593, in run
    self._callTestMethod(testMethod)
    │    │               └ <bound method TestURLListing.test_listing_with_db_error of <tests.test_url_listing.TestURLListing testMethod=test_listing_wit...
    │    └ <function TestCase._callTestMethod at 0x0000022C050CC5E0>
    └ <tests.test_url_listing.TestURLListing testMethod=test_listing_with_db_error>

  File "C:\Users\Camden\AppData\Local\Programs\Python\Python39\lib\unittest\case.py", line 550, in _callTestMethod
    method()
    └ <bound method TestURLListing.test_listing_with_db_error of <tests.test_url_listing.TestURLListing testMethod=test_listing_wit...

  File "C:\Users\Camden\AppData\Local\Programs\Python\Python39\lib\unittest\mock.py", line 1337, in patched
    return func(*newargs, **newkeywargs)
           │     │          └ {}
           │     └ (<tests.test_url_listing.TestURLListing testMethod=test_listing_with_db_error>, <MagicMock name='scan' id='2388171438496'>)
           └ <function TestURLListing.test_listing_with_db_error at 0x0000022C0A446670>

  File "C:\Users\Camden\PycharmProjects\url-shortener\tests\test_url_listing.py", line 28, in test_listing_with_db_error
    get_all_urls()
    └ <function get_all_urls at 0x0000022C09ED2040>

> File "C:\Users\Camden\PycharmProjects\url-shortener\service\db_service.py", line 50, in get_all_urls
    urls = [item for item in URLModel.scan()]
                             │        └ <MagicMock name='scan' id='2388171438496'>
                             └ <class 'models.db_models.URLModel'>

  File "C:\Users\Camden\AppData\Local\Programs\Python\Python39\lib\unittest\mock.py", line 1093, in __call__
    return self._mock_call(*args, **kwargs)
           │    │           │       └ {}
           │    │           └ ()
           │    └ <function CallableMixin._mock_call at 0x0000022C06E8C700>
           └ <MagicMock name='scan' id='2388171438496'>

  File "C:\Users\Camden\AppData\Local\Programs\Python\Python39\lib\unittest\mock.py", line 1097, in _mock_call
    return self._execute_mock_call(*args, **kwargs)
           │    │                   │       └ {}
           │    │                   └ ()
           │    └ <function CallableMixin._execute_mock_call at 0x0000022C06E8C820>
           └ <MagicMock name='scan' id='2388171438496'>

  File "C:\Users\Camden\AppData\Local\Programs\Python\Python39\lib\unittest\mock.py", line 1152, in _execute_mock_call
    raise effect
          └ ConnectionError('DB connection error')

ConnectionError: DB connection error
2023-11-03T17:15:12.300901-0600 INFO Retrieved all URLs from the database.
2023-11-03T17:15:12.300901-0600 INFO Retrieved all URLs from the database.
2023-11-03T17:15:15.725439-0600 WARNING Short URL does not exist
2023-11-03T17:15:15.727441-0600 WARNING Short URL does not exist
2023-11-03T17:15:15.728438-0600 INFO Retrieved original URL for short URL: validShort
